Workbook
Name Decision: Lists!$D$94:$D$96
Name Fit: Lists!$D$67:$D$70
Name InterviewType: Lists!$D$99:$D$104
Name JobType: Lists!$D$44:$D$48
Name Priority: Lists!$D$23:$D$25
Name Response: Lists!$D$51:$D$54
Name Seniority: Lists!$D$57:$D$64
Name Source: Lists!$D$28:$D$36
Name Stage: Lists!$D$15:$D$20
Name Status: Lists!$D$2:$D$12
Name TaskStatus: Lists!$D$88:$D$91
Name TaskType: Lists!$D$78:$D$85
Name Visa: Lists!$D$73:$D$75
Name WorkMode: Lists!$D$39:$D$41
Name YesNo: Lists!$D$107:$D$108

Sheet Applications
A1: Job ID | B1: Company | C1: Job Title | D1: Job Posting Link | E1: Source | F1: Referral Name | G1: Work Mode | H1: Location | I1: Job Type | J1: Seniority | K1: Comp Range | L1: Target Comp | M1: Date Found | N1: Date Applied | O1: Status | P1: Stage | Q1: Priority | R1: Fit (You) | S1: Key Skills Matched | T1: Tech Stack / Keywords | U1: ATS Keywords Used | V1: Resume Version | W1: Cover Letter (Y/N) | X1: Portfolio/GitHub | Y1: Visa/Sponsorship | Z1: Last Activity Date | AA1: Next Follow-Up Date | AB1: Days Since Activity | AC1: Response / Feedback | AD1: Recruiter / Primary Contact | AE1: Notes

Sheet Dashboard
A1: Job Application Tracker Dashboard
A3: KPI | B3: Value | D3: Status Summary
A4: Total Applications | B4: =COUNTA(Applications!B2:B1999) -> 0 | D4: Status | E4: Count
A5: Active (Not Closed) | B5: =COUNTIFS(Applications!B2:B1999,"<>",Applications!O2:O1999,"<>Rejected",Applications!O2:O1999,"<>Withdrawn") -> 0 | D5: Interested | E5: =COUNTIF(Applications!O2:O1999,"Interested") -> 0
A6: Interviews Logged | B6: =COUNTA(Interviews!B2:B2000) -> 0 | D6: Applied | E6: =COUNTIF(Applications!O2:O1999,"Applied") -> 0
A7: Offers | B7: =COUNTIF(Applications!O2:O1999,"Offer") -> 0 | D7: Recruiter Screen | E7: =COUNTIF(Applications!O2:O1999,"Recruiter Screen") -> 0
A8: Follow-ups Due (Next 2 days) | B8: =COUNTIFS(Applications!AA2:AA1999,">="&TODAY(),Applications!AA2:AA1999,"<="&TODAY()+2,Applications!O2:O1999,"<>Rejected",Applications!O2:O1999,"<>Withdrawn") -> 0 | D8: Hiring Manager Screen | E8: =COUNTIF(Applications!O2:O1999,"Hiring Manager Screen") -> 0
A9: Overdue Follow-ups | B9: =COUNTIFS(Applications!AA2:AA1999,"<"&TODAY(),Applications!O2:O1999,"<>Rejected",Applications!O2:O1999,"<>Withdrawn") -> 0 | D9: Assessment | E9: =COUNTIF(Applications!O2:O1999,"Assessment") -> 0
D10: Interview - Round 1 | E10: =COUNTIF(Applications!O2:O1999,"Interview - Round 1") -> 0
A11: Quick Start | D11: Interview - Round 2+ | E11: =COUNTIF(Applications!O2:O1999,"Interview - Round 2+") -> 0
A12: 1) Log every job on Applications (one row per job). | D12: Offer | E12: =COUNTIF(Applications!O2:O1999,"Offer") -> 0
A13: 2) Update Status + Last Activity Date whenever something happens. | D13: Rejected | E13: =COUNTIF(Applications!O2:O1999,"Rejected") -> 0
A14: 3) Use Next Follow-Up Date to drive your daily outreach. | D14: Withdrawn | E14: =COUNTIF(Applications!O2:O1999,"Withdrawn") -> 0
A15: 4) Log recruiter/hiring manager info in Contacts. | D15: On Hold | E15: =COUNTIF(Applications!O2:O1999,"On Hold") -> 0
A16: 5) Track tasks (thank-you notes, follow-ups, prep) in Follow-ups.
A17: Tip: You can overwrite any formula cell (Last Activity / Next Follow-up) if you want manual control.

Sheet Follow-ups
A1: Task ID | B1: Job ID | C1: Company | D1: Job Title | E1: Task Type | F1: Task Status | G1: Owner | H1: Due Date | I1: Completed Date | J1: Days Overdue | K1: Notes
A2: =IF(B2="","","T-"&TEXT(ROW()-1,"0000")) | J2: =IF(F2="","",IF(F2="Done",0,MAX(0,TODAY()-H2)))
A3: =IF(B3="","","T-"&TEXT(ROW()-1,"0000")) | J3: =IF(F3="","",IF(F3="Done",0,MAX(0,TODAY()-H3)))
A4: =IF(B4="","","T-"&TEXT(ROW()-1,"0000")) | J4: =IF(F4="","",IF(F4="Done",0,MAX(0,TODAY()-H4)))
A5: =IF(B5="","","T-"&TEXT(ROW()-1,"0000")) | J5: =IF(F5="","",IF(F5="Done",0,MAX(0,TODAY()-H5)))
A6: =IF(B6="","","T-"&TEXT(ROW()-1,"0000")) | J6: =IF(F6="","",IF(F6="Done",0,MAX(0,TODAY()-H6)))
A7: =IF(B7="","","T-"&TEXT(ROW()-1,"0000")) | J7: =IF(F7="","",IF(F7="Done",0,MAX(0,TODAY()-H7)))
A8: =IF(B8="","","T-"&TEXT(ROW()-1,"0000")) | J8: =IF(F8="","",IF(F8="Done",0,MAX(0,TODAY()-H8)))
A9: =IF(B9="","","T-"&TEXT(ROW()-1,"0000")) | J9: =IF(F9="","",IF(F9="Done",0,MAX(0,TODAY()-H9)))
A10: =IF(B10="","","T-"&TEXT(ROW()-1,"0000")) | J10: =IF(F10="","",IF(F10="Done",0,MAX(0,TODAY()-H10)))
A11: =IF(B11="","","T-"&TEXT(ROW()-1,"0000")) | J11: =IF(F11="","",IF(F11="Done",0,MAX(0,TODAY()-H11)))
A12: =IF(B12="","","T-"&TEXT(ROW()-1,"0000")) | J12: =IF(F12="","",IF(F12="Done",0,MAX(0,TODAY()-H12)))
A13: =IF(B13="","","T-"&TEXT(ROW()-1,"0000")) | J13: =IF(F13="","",IF(F13="Done",0,MAX(0,TODAY()-H13)))
... A2000: =IF(B2000="","","T-"&TEXT(ROW()-1,"0000")) | J2000: =IF(F2000="","",IF(F2000="Done",0,MAX(0,TODAY()-H2000)))

Sheet Interviews
A1: Interview ID | B1: Job ID | C1: Company | D1: Job Title | E1: Round | F1: Interview Type | G1: Interview Date | H1: Interview Time | I1: Interviewer(s) | J1: Decision | K1: Thank You Sent (Y/N) | L1: Notes
A2: =IF(B2="","","I-"&TEXT(ROW()-1,"0000"))
A3: =IF(B3="","","I-"&TEXT(ROW()-1,"0000"))
A4: =IF(B4="","","I-"&TEXT(ROW()-1,"0000"))
A5: =IF(B5="","","I-"&TEXT(ROW()-1,"0000"))
A6: =IF(B6="","","I-"&TEXT(ROW()-1,"0000"))
A7: =IF(B7="","","I-"&TEXT(ROW()-1,"0000"))
A8: =IF(B8="","","I-"&TEXT(ROW()-1,"0000"))
A9: =IF(B9="","","I-"&TEXT(ROW()-1,"0000"))
A10: =IF(B10="","","I-"&TEXT(ROW()-1,"0000"))
A11: =IF(B11="","","I-"&TEXT(ROW()-1,"0000"))
A12: =IF(B12="","","I-"&TEXT(ROW()-1,"0000"))
A13: =IF(B13="","","I-"&TEXT(ROW()-1,"0000"))
... A2000: =IF(B2000="","","I-"&TEXT(ROW()-1,"0000"))

Sheet Contacts
A1: Contact ID | B1: Name | C1: Title | D1: Company | E1: Email | F1: Phone | G1: LinkedIn | H1: Relationship | I1: Last Contacted Date | J1: Next Action Date | K1: Linked Job ID | L1: Notes
A2: =IF(B2="","","C-"&TEXT(ROW()-1,"0000"))
A3: =IF(B3="","","C-"&TEXT(ROW()-1,"0000"))
A4: =IF(B4="","","C-"&TEXT(ROW()-1,"0000"))
A5: =IF(B5="","","C-"&TEXT(ROW()-1,"0000"))
A6: =IF(B6="","","C-"&TEXT(ROW()-1,"0000"))
A7: =IF(B7="","","C-"&TEXT(ROW()-1,"0000"))
A8: =IF(B8="","","C-"&TEXT(ROW()-1,"0000"))
A9: =IF(B9="","","C-"&TEXT(ROW()-1,"0000"))
A10: =IF(B10="","","C-"&TEXT(ROW()-1,"0000"))
A11: =IF(B11="","","C-"&TEXT(ROW()-1,"0000"))
A12: =IF(B12="","","C-"&TEXT(ROW()-1,"0000"))
A13: =IF(B13="","","C-"&TEXT(ROW()-1,"0000"))
... A2000: =IF(B2000="","","C-"&TEXT(ROW()-1,"0000"))

Sheet Lists
A1: List Name | B1: Named Range
A2: Status | B2: =Status -> Interested | D2: Interested
D3: Applied
D4: Recruiter Screen
D5: Hiring Manager Screen
D6: Assessment
D7: Interview - Round 1
D8: Interview - Round 2+
D9: Offer
D10: Rejected
D11: Withdrawn
D12: On Hold
A15: Stage | B15: =Stage -> Applied | D15: Applied
D16: Screen
D17: Assessment
D18: Interview
D19: Offer
D20: Closed
A23: Priority | B23: =Priority -> High | D23: High
D24: Medium
D25: Low
A28: Source | B28: =Source -> LinkedIn | D28: LinkedIn
D29: Company Site
D30: Indeed
D31: Referral
D32: Recruiter Outreach
D33: Networking
D34: Job Board (Other)
D35: Internal
D36: Other
A39: WorkMode | B39: =WorkMode -> Remote | D39: Remote
D40: Hybrid
D41: On-site
A44: JobType | B44: =JobType -> Full-time | D44: Full-time
D45: Contract
D46: Contract-to-hire
D47: Part-time
D48: Internship
A51: Response | B51: =Response -> No response | D51: No response
D52: In progress
...
